Workbook

Sheet Dashboard
B1: Customer Churn KPI Dashboard
B2: 15 synthetic customer records. Pick values in the yellow cells; every KPI, table and chart recalculates.
B3: FILTERS
B4: Contract type | C4: All | D4: Set a filter back to "All" to clear it.
B5: Tenure band | C5: All
B6: Payment method | C6: All | D6: =SUM(Data!$N$2:$N$16)&" of 15 customers in view" -> 15 of 15 customers in view
B8: KEY METRICS
B10: Customers in view | C10: =SUM(Data!$N$2:$N$16) -> 15
B11: Churn rate | C11: =IFERROR(C13/C10,0) -> 0.46666667 | D11: Churned / customers in view
B12: Retention rate | C12: =IF(C10=0,0,1-C11) -> 0.53333333 | D12: 1 - churn rate
B13: Churned customers | C13: =SUMPRODUCT(Data!$N$2:$N$16,Data!$M$2:$M$16) -> 7
B14: Total MRR in view | C14: =SUMPRODUCT(Data!$N$2:$N$16,Data!$F$2:$F$16) -> 1269.85 | D14: Sum of MonthlyCharges
B15: Revenue lost (MRR) | C15: =SUMPRODUCT(Data!$N$2:$N$16,Data!$M$2:$M$16,Data!$F$2:$F$16) -> 409.93 | D15: MRR of churned customers
B16: Revenue lost, % of MRR | C16: =IFERROR(C15/C14,0) -> 0.32281766
B17: Revenue at risk (MRR) | C17: =SUMPRODUCT(Data!$O$2:$O$16,Data!$F$2:$F$16) -> 0 | D17: Active customers on Month-to-Month or with 3+ tickets
B18: Avg tenure, all (months) | C18: =IFERROR(SUMPRODUCT(Data!$N$2:$N$16,Data!$D$2:$D$16)/C10,0) -> 18.8
B19: Avg tenure, churned | C19: =IFERROR(SUMPRODUCT(Data!$N$2:$N$16,Data!$M$2:$M$16,Data!$D$2:$D$16)/C13,0) -> 7
B20: Avg tenure, retained | C20: =IFERROR(SUMPRODUCT(Data!$N$2:$N$16,1-Data!$M$2:$M$16,Data!$D$2:$D$16)/(C10-C13),0) -> 29.125
B23: Churn by contract type
B24: Contract | C24: Churned | D24: Retained | E24: Customers | F24: Churn rate
B25: Month-to-Month | C25: =SUMPRODUCT(Data!$N$2:$N$16*Data!$M$2:$M$16*(Data!$H$2:$H$16=$B25)) -> 7 | D25: =E25-C25 -> 0 | E25: =SUMPRODUCT(Data!$N$2:$N$16*(Data!$H$2:$H$16=$B25)) -> 7 | F25: =IFERROR(C25/E25,0) -> 1
B26: One Year | C26: =SUMPRODUCT(Data!$N$2:$N$16*Data!$M$2:$M$16*(Data!$H$2:$H$16=$B26)) -> 0 | D26: =E26-C26 -> 4 | E26: =SUMPRODUCT(Data!$N$2:$N$16*(Data!$H$2:$H$16=$B26)) -> 4 | F26: =IFERROR(C26/E26,0) -> 0
B27: Two Year | C27: =SUMPRODUCT(Data!$N$2:$N$16*Data!$M$2:$M$16*(Data!$H$2:$H$16=$B27)) -> 0 | D27: =E27-C27 -> 4 | E27: =SUMPRODUCT(Data!$N$2:$N$16*(Data!$H$2:$H$16=$B27)) -> 4 | F27: =IFERROR(C27/E27,0) -> 0
B38: Churn by tenure band
B39: Tenure band | C39: Churned | D39: Retained | E39: Customers | F39: Churn rate
B40: 0-6 mo | C40: =SUMPRODUCT(Data!$N$2:$N$16*Data!$M$2:$M$16*(Data!$L$2:$L$16=$B40)) -> 4 | D40: =E40-C40 -> 0 | E40: =SUMPRODUCT(Data!$N$2:$N$16*(Data!$L$2:$L$16=$B40)) -> 4 | F40: =IFERROR(C40/E40,0) -> 1
B41: 7-12 mo | C41: =SUMPRODUCT(Data!$N$2:$N$16*Data!$M$2:$M$16*(Data!$L$2:$L$16=$B41)) -> 2 | D41: =E41-C41 -> 0 | E41: =SUMPRODUCT(Data!$N$2:$N$16*(Data!$L$2:$L$16=$B41)) -> 2 | F41: =IFERROR(C41/E41,0) -> 1
B42: 13-24 mo | C42: =SUMPRODUCT(Data!$N$2:$N$16*Data!$M$2:$M$16*(Data!$L$2:$L$16=$B42)) -> 1 | D42: =E42-C42 -> 4 | E42: =SUMPRODUCT(Data!$N$2:$N$16*(Data!$L$2:$L$16=$B42)) -> 5 | F42: =IFERROR(C42/E42,0) -> 0.2
B43: 25+ mo | C43: =SUMPRODUCT(Data!$N$2:$N$16*Data!$M$2:$M$16*(Data!$L$2:$L$16=$B43)) -> 0 | D43: =E43-C43 -> 4 | E43: =SUMPRODUCT(Data!$N$2:$N$16*(Data!$L$2:$L$16=$B43)) -> 4 | F43: =IFERROR(C43/E43,0) -> 0
B53: Churn by payment method
B54: Payment | C54: Churned | D54: Retained | E54: Customers | F54: Churn rate
B55: Bank Transfer | C55: =SUMPRODUCT(Data!$N$2:$N$16*Data!$M$2:$M$16*(Data!$J$2:$J$16=$B55)) -> 0 | D55: =E55-C55 -> 3 | E55: =SUMPRODUCT(Data!$N$2:$N$16*(Data!$J$2:$J$16=$B55)) -> 3 | F55: =IFERROR(C55/E55,0) -> 0
B56: Credit Card | C56: =SUMPRODUCT(Data!$N$2:$N$16*Data!$M$2:$M$16*(Data!$J$2:$J$16=$B56)) -> 2 | D56: =E56-C56 -> 4 | E56: =SUMPRODUCT(Data!$N$2:$N$16*(Data!$J$2:$J$16=$B56)) -> 6 | F56: =IFERROR(C56/E56,0) -> 0.33333333
B57: Debit Card | C57: =SUMPRODUCT(Data!$N$2:$N$16*Data!$M$2:$M$16*(Data!$J$2:$J$16=$B57)) -> 2 | D57: =E57-C57 -> 0 | E57: =SUMPRODUCT(Data!$N$2:$N$16*(Data!$J$2:$J$16=$B57)) -> 2 | F57: =IFERROR(C57/E57,0) -> 1
B58: UPI | C58: =SUMPRODUCT(Data!$N$2:$N$16*Data!$M$2:$M$16*(Data!$J$2:$J$16=$B58)) -> 3 | D58: =E58-C58 -> 1 | E58: =SUMPRODUCT(Data!$N$2:$N$16*(Data!$J$2:$J$16=$B58)) -> 4 | F58: =IFERROR(C58/E58,0) -> 0.75
B68: Monthly revenue by plan
B69: Plan | C69: MRR lost | D69: MRR retained | E69: Total MRR | F69: Lost %
B70: Basic | C70: =SUMPRODUCT(Data!$N$2:$N$16*Data!$M$2:$M$16*Data!$F$2:$F$16*(Data!$E$2:$E$16=$B70)) -> 249.95 | D70: =E70-C70 -> 99.98 | E70: =SUMPRODUCT(Data!$N$2:$N$16*Data!$F$2:$F$16*(Data!$E$2:$E$16=$B70)) -> 349.93 | F70: =IFERROR(C70/E70,0) -> 0.71428571
B71: Pro | C71: =SUMPRODUCT(Data!$N$2:$N$16*Data!$M$2:$M$16*Data!$F$2:$F$16*(Data!$E$2:$E$16=$B71)) -> 159.98 | D71: =E71-C71 -> 159.98 | E71: =SUMPRODUCT(Data!$N$2:$N$16*Data!$F$2:$F$16*(Data!$E$2:$E$16=$B71)) -> 319.96 | F71: =IFERROR(C71/E71,0) -> 0.5
B72: Enterprise | C72: =SUMPRODUCT(Data!$N$2:$N$16*Data!$M$2:$M$16*Data!$F$2:$F$16*(Data!$E$2:$E$16=$B72)) -> 0 | D72: =E72-C72 -> 599.96 | E72: =SUMPRODUCT(Data!$N$2:$N$16*Data!$F$2:$F$16*(Data!$E$2:$E$16=$B72)) -> 599.96 | F72: =IFERROR(C72/E72,0) -> 0
...

Sheet Data
A1: CustomerID | B1: Gender | C1: Age | D1: TenureMonths | E1: SubscriptionType | F1: MonthlyCharges | G1: TotalCharges | H1: ContractType | I1: SupportTickets | J1: PaymentMethod | K1: Churn | L1: TenureBand | M1: ChurnFlag | N1: InView | O1: AtRisk | Q1: Columns L-O are formulas: tenure band, churn flag (1 = churned), InView (1 = row matches the Dashboard filters), AtRisk (1 = active customer on Month-to-Month or with 3+ tickets).
A2: CUST-1001 | B2: Female | C2: 34 | D2: 12 | E2: Basic | F2: 49.99 | G2: 599.88 | H2: Month-to-Month | I2: 3 | J2: Credit Card | K2: Yes | L2: =IF(D2<=6,"0-6 mo",IF(D2<=12,"7-12 mo",IF(D2<=24,"13-24 mo","25+ mo"))) -> 7-12 mo | M2: =IF(K2="Yes",1,0) -> 1 | N2: =IF(AND(OR(Dashboard!$C$4="All",H2=Dashboard!$C$4),OR(Dashboard!$C$5="All",L2=Dashboard!$C$5),OR(Dashboard!$C$6="All",J2=Dashboard!$C$6)),1,0) -> 1 | O2: =IF(AND(N2=1,M2=0,OR(H2="Month-to-Month",I2>=3)),1,0) -> 0
A3: CUST-1002 | B3: Male | C3: 45 | D3: 24 | E3: Pro | F3: 79.99 | G3: 1919.76 | H3: One Year | I3: 1 | J3: Bank Transfer | K3: No | L3: =IF(D3<=6,"0-6 mo",IF(D3<=12,"7-12 mo",IF(D3<=24,"13-24 mo","25+ mo"))) -> 13-24 mo | M3: =IF(K3="Yes",1,0) -> 0 | N3: =IF(AND(OR(Dashboard!$C$4="All",H3=Dashboard!$C$4),OR(Dashboard!$C$5="All",L3=Dashboard!$C$5),OR(Dashboard!$C$6="All",J3=Dashboard!$C$6)),1,0) -> 1 | O3: =IF(AND(N3=1,M3=0,OR(H3="Month-to-Month",I3>=3)),1,0) -> 0
A4: CUST-1003 | B4: Female | C4: 29 | D4: 6 | E4: Basic | F4: 49.99 | G4: 299.94 | H4: Month-to-Month | I4: 5 | J4: UPI | K4: Yes | L4: =IF(D4<=6,"0-6 mo",IF(D4<=12,"7-12 mo",IF(D4<=24,"13-24 mo","25+ mo"))) -> 0-6 mo | M4: =IF(K4="Yes",1,0) -> 1 | N4: =IF(AND(OR(Dashboard!$C$4="All",H4=Dashboard!$C$4),OR(Dashboard!$C$5="All",L4=Dashboard!$C$5),OR(Dashboard!$C$6="All",J4=Dashboard!$C$6)),1,0) -> 1 | O4: =IF(AND(N4=1,M4=0,OR(H4="Month-to-Month",I4>=3)),1,0) -> 0
A5: CUST-1004 | B5: Male | C5: 52 | D5: 36 | E5: Enterprise | F5: 149.99 | G5: 5399.64 | H5: Two Year | I5: 0 | J5: Credit Card | K5: No | L5: =IF(D5<=6,"0-6 mo",IF(D5<=12,"7-12 mo",IF(D5<=24,"13-24 mo","25+ mo"))) -> 25+ mo | M5: =IF(K5="Yes",1,0) -> 0 | N5: =IF(AND(OR(Dashboard!$C$4="All",H5=Dashboard!$C$4),OR(Dashboard!$C$5="All",L5=Dashboard!$C$5),OR(Dashboard!$C$6="All",J5=Dashboard!$C$6)),1,0) -> 1 | O5: =IF(AND(N5=1,M5=0,OR(H5="Month-to-Month",I5>=3)),1,0) -> 0
A6: CUST-1005 | B6: Female | C6: 41 | D6: 8 | E6: Pro | F6: 79.99 | G6: 639.92 | H6: Month-to-Month | I6: 4 | J6: Debit Card | K6: Yes | L6: =IF(D6<=6,"0-6 mo",IF(D6<=12,"7-12 mo",IF(D6<=24,"13-24 mo","25+ mo"))) -> 7-12 mo | M6: =IF(K6="Yes",1,0) -> 1 | N6: =IF(AND(OR(Dashboard!$C$4="All",H6=Dashboard!$C$4),OR(Dashboard!$C$5="All",L6=Dashboard!$C$5),OR(Dashboard!$C$6="All",J6=Dashboard!$C$6)),1,0) -> 1 | O6: =IF(AND(N6=1,M6=0,OR(H6="Month-to-Month",I6>=3)),1,0) -> 0
A7: CUST-1006 | B7: Male | C7: 31 | D7: 18 | E7: Basic | F7: 49.99 | G7: 899.82 | H7: One Year | I7: 2 | J7: UPI | K7: No | L7: =IF(D7<=6,"0-6 mo",IF(D7<=12,"7-12 mo",IF(D7<=24,"13-24 mo","25+ mo"))) -> 13-24 mo | M7: =IF(K7="Yes",1,0) -> 0 | N7: =IF(AND(OR(Dashboard!$C$4="All",H7=Dashboard!$C$4),OR(Dashboard!$C$5="All",L7=Dashboard!$C$5),OR(Dashboard!$C$6="All",J7=Dashboard!$C$6)),1,0) -> 1 | O7: =IF(AND(N7=1,M7=0,OR(H7="Month-to-Month",I7>=3)),1,0) -> 0
A8: CUST-1007 | B8: Female | C8: 23 | D8: 3 | E8: Basic | F8: 49.99 | G8: 149.97 | H8: Month-to-Month | I8: 6 | J8: Credit Card | K8: Yes | L8: =IF(D8<=6,"0-6 mo",IF(D8<=12,"7-12 mo",IF(D8<=24,"13-24 mo","25+ mo"))) -> 0-6 mo | M8: =IF(K8="Yes",1,0) -> 1 | N8: =IF(AND(OR(Dashboard!$C$4="All",H8=Dashboard!$C$4),OR(Dashboard!$C$5="All",L8=Dashboard!$C$5),OR(Dashboard!$C$6="All",J8=Dashboard!$C$6)),1,0) -> 1 | O8: =IF(AND(N8=1,M8=0,OR(H8="Month-to-Month",I8>=3)),1,0) -> 0
A9: CUST-1008 | B9: Male | C9: 60 | D9: 48 | E9: Enterprise | F9: 149.99 | G9: 7199.52 | H9: Two Year | I9: 1 | J9: Bank Transfer | K9: No | L9: =IF(D9<=6,"0-6 mo",IF(D9<=12,"7-12 mo",IF(D9<=24,"13-24 mo","25+ mo"))) -> 25+ mo | M9: =IF(K9="Yes",1,0) -> 0 | N9: =IF(AND(OR(Dashboard!$C$4="All",H9=Dashboard!$C$4),OR(Dashboard!$C$5="All",L9=Dashboard!$C$5),OR(Dashboard!$C$6="All",J9=Dashboard!$C$6)),1,0) -> 1 | O9: =IF(AND(N9=1,M9=0,OR(H9="Month-to-Month",I9>=3)),1,0) -> 0
A10: CUST-1009 | B10: Female | C10: 38 | D10: 15 | E10: Pro | F10: 79.99 | G10: 1199.85 | H10: One Year | I10: 2 | J10: Credit Card | K10: No | L10: =IF(D10<=6,"0-6 mo",IF(D10<=12,"7-12 mo",IF(D10<=24,"13-24 mo","25+ mo"))) -> 13-24 mo | M10: =IF(K10="Yes",1,0) -> 0 | N10: =IF(AND(OR(Dashboard!$C$4="All",H10=Dashboard!$C$4),OR(Dashboard!$C$5="All",L10=Dashboard!$C$5),OR(Dashboard!$C$6="All",J10=Dashboard!$C$6)),1,0) -> 1 | O10: =IF(AND(N10=1,M10=0,OR(H10="Month-to-Month",I10>=3)),1,0) -> 0
A11: CUST-1010 | B11: Male | C11: 27 | D11: 4 | E11: Basic | F11: 49.99 | G11: 199.96 | H11: Month-to-Month | I11: 4 | J11: UPI | K11: Yes | L11: =IF(D11<=6,"0-6 mo",IF(D11<=12,"7-12 mo",IF(D11<=24,"13-24 mo","25+ mo"))) -> 0-6 mo | M11: =IF(K11="Yes",1,0) -> 1 | N11: =IF(AND(OR(Dashboard!$C$4="All",H11=Dashboard!$C$4),OR(Dashboard!$C$5="All",L11=Dashboard!$C$5),OR(Dashboard!$C$6="All",J11=Dashboard!$C$6)),1,0) -> 1 | O11: =IF(AND(N11=1,M11=0,OR(H11="Month-to-Month",I11>=3)),1,0) -> 0
A12: CUST-1011 | B12: Female | C12: 49 | D12: 30 | E12: Enterprise | F12: 149.99 | G12: 4499.7 | H12: Two Year | I12: 0 | J12: Credit Card | K12: No | L12: =IF(D12<=6,"0-6 mo",IF(D12<=12,"7-12 mo",IF(D12<=24,"13-24 mo","25+ mo"))) -> 25+ mo | M12: =IF(K12="Yes",1,0) -> 0 | N12: =IF(AND(OR(Dashboard!$C$4="All",H12=Dashboard!$C$4),OR(Dashboard!$C$5="All",L12=Dashboard!$C$5),OR(Dashboard!$C$6="All",J12=Dashboard!$C$6)),1,0) -> 1 | O12: =IF(AND(N12=1,M12=0,OR(H12="Month-to-Month",I12>=3)),1,0) -> 0
A13: CUST-1012 | B13: Male | C13: 33 | D13: 14 | E13: Pro | F13: 79.99 | G13: 1119.86 | H13: Month-to-Month | I13: 3 | J13: Debit Card | K13: Yes | L13: =IF(D13<=6,"0-6 mo",IF(D13<=12,"7-12 mo",IF(D13<=24,"13-24 mo","25+ mo"))) -> 13-24 mo | M13: =IF(K13="Yes",1,0) -> 1 | N13: =IF(AND(OR(Dashboard!$C$4="All",H13=Dashboard!$C$4),OR(Dashboard!$C$5="All",L13=Dashboard!$C$5),OR(Dashboard!$C$6="All",J13=Dashboard!$C$6)),1,0) -> 1 | O13: =IF(AND(N13=1,M13=0,OR(H13="Month-to-Month",I13>=3)),1,0) -> 0
... A16: CUST-1015 | B16: Female | C16: 43 | D16: 40 | E16: Enterprise | F16: 149.99 | G16: 5999.6 | H16: Two Year | I16: 1 | J16: Credit Card | K16: No | L16: =IF(D16<=6,"0-6 mo",IF(D16<=12,"7-12 mo",IF(D16<=24,"13-24 mo","25+ mo"))) -> 25+ mo | M16: =IF(K16="Yes",1,0) -> 0 | N16: =IF(AND(OR(Dashboard!$C$4="All",H16=Dashboard!$C$4),OR(Dashboard!$C$5="All",L16=Dashboard!$C$5),OR(Dashboard!$C$6="All",J16=Dashboard!$C$6)),1,0) -> 1 | O16: =IF(AND(N16=1,M16=0,OR(H16="Month-to-Month",I16>=3)),1,0) -> 0
